//
//  Completion.swift
//  FutureKit
//
//  Created by Michael Gray on 4/21/15.
// Permission is hereby granted, free of charge, to any person obtaining a copy
// of this software and associated documentation files (the "Software"), to deal
// in the Software without restriction, including without limitation the rights
// to use, copy, modify, merge, publish, distribute, sublicense, and/or sell
// copies of the Software, and to permit persons to whom the Software is
// furnished to do so, subject to the following conditions:
//
// The above copyright notice and this permission notice shall be included in
// all copies or substantial portions of the Software.
//
// THE SOFTWARE IS PROVIDED "AS IS", WITHOUT WARRANTY OF ANY KIND, EXPRESS OR
// IMPLIED, INCLUDING BUT NOT LIMITED TO THE WARRANTIES OF MERCHANTABILITY,
// FITNESS FOR A PARTICULAR PURPOSE AND NONINFRINGEMENT. IN NO EVENT SHALL THE
// AUTHORS OR COPYRIGHT HOLDERS BE LIABLE FOR ANY CLAIM, DAMAGES OR OTHER
// LIABILITY, WHETHER IN AN ACTION OF CONTRACT, TORT OR OTHERWISE, ARISING FROM,
// OUT OF OR IN CONNECTION WITH THE SOFTWARE OR THE USE OR OTHER DEALINGS IN
// THE SOFTWARE.
//

import Foundation


// the onSuccess and onComplete handlers will return either a generic type __Type, or any object confirming to the CompletionType.

//    CompletionType include Completion<T>, FutureResult<T>, Future<T>, Promise<T>...


public protocol CompletionType : CustomStringConvertible, CustomDebugStringConvertible {
    typealias T
    
    var completion : Completion<T> { get }
    
}


// a type-erased CompletionType
public struct AnyCompletion : CompletionType {
    public typealias T = Any
    
    public var completion : Completion<Any>
   
    init<C:CompletionType>(completionType:C) {
        self.completion = completionType.completion.mapAs()
    }
    
}

extension CompletionType {
    func toAnyCompletion() -> AnyCompletion {
        return AnyCompletion(completionType: self)
    }
}


/**
Defines a simple enumeration of the legal Completion states of a Future.

- case Success(T):      the Future has completed Succesfully.
- case Fail(ErrorType): the Future has failed.
- case Cancelled:       the Future was cancelled. This is typically not seen as an error.

*/
public enum FutureResult<T>  {
    
    case Success(T)
    case Fail(ErrorType)
    case Cancelled

}


/**
Defines a an enumeration that can be used to complete a Promise/Future.

- Success(T): The Future should complete with a `FutureResult.Success(T)`

- Fail(ErrorType): The Future should complete with a `FutureResult.Fail(ErrorType)`

- Cancelled:  
    The Future should complete with with `FutureResult.Cancelled`.

- CompleteUsing(Future<T>):  
    The Future should be completed with the result of a another dependent Future, when the dependent Future completes.
    
    If The Future receives a cancelation request, than the cancellation request will be forwarded to the depedent future.
*/
public enum Completion<T>  {
    
    case Success(T)
    case Fail(ErrorType)
    case Cancelled
    case CompleteUsing(Future<T>)
}



extension Future : CompletionType {
    
    public var completion : Completion<T> {
        return .CompleteUsing(self)
    }
    
}

extension Promise : CompletionType {
    
    public var completion : Completion<T> {
        return .CompleteUsing(self.future)
    }
}

extension Completion : CompletionType { // properties
    
    public var completion : Completion<T> {
        return self
    }
}


extension FutureResult : CompletionType {
    
    public var completion : Completion<T> {
        switch self {
        case let .Success(result):
            return .Success(result)
        case let .Fail(error):
            return error.toCompletion()
        case .Cancelled:
            return .Cancelled
        }
    }
    
}

public func SUCCESS<T>(value:T) -> Completion<T>  {
    return Completion<T>(success: value)
}

public func FAIL<T>(fail:ErrorType) -> Completion<T> {
    return Completion<T>(fail: fail)
}

public func CANCELLED<T>(cancelled:()) -> Completion<T> {
    return Completion<T>(cancelled: cancelled)
}

public func COMPLETE_USING<T>(completeUsing:Future<T>) -> Completion<T> {
    return Completion<T>(completeUsing: completeUsing)
}



public extension FutureResult { // initializers
    
    /**
    returns a .Fail(FutureNSError) with a simple error string message.
    */
    public init(failWithErrorMessage : String) {
        self = .Fail(FutureKitError(genericError: failWithErrorMessage))
    }
    /**
    converts an NSException into an NSError.
    useful for generic Objective-C excecptions into a Future
    */
    public init(exception ex:NSException) {
        self = .Fail(FutureKitError(exception: ex))
    }
    
    public init(success:T) {
        self = .Success(success)
    }
    
    public init(fail: ErrorType) {
        self = .Fail(fail)
    }
    public init(cancelled: ()) {
        self = .Cancelled
    }

}

public extension CompletionType {
    /**
    make sure this enum is a .Success before calling `result`. Do a check 'completion.state {}` or .isFail() first.
    */
    public var value : T! {
        get {
            switch self.completion {
            case let .Success(t):
                return t
            case let .CompleteUsing(f):
                if let v = f.value {
                    return v
                }
                else {
                    return nil
                }
            default:
                return nil
            }
        }
    }
    /**
    make sure this enum is a .Fail before calling `result`. Use a switch or check .isError() first.
    */
    public var error : ErrorType! {
        get {
            switch self.completion {
            case let .Fail(e):
                return e.testForCancellation ? nil : e
            default:
                return nil
            }
        }
    }
    
    public var isSuccess : Bool {
        get {
            switch self.completion {
            case .Success:
                return true
            default:
                return false
            }
        }
    }
    public var isFail : Bool {
        get {
            switch self.completion {
            case let .Fail(e):
                return !e.testForCancellation
            default:
                return false
            }
        }
    }
    public var isCancelled : Bool {
        get {
            switch self.completion {
            case .Cancelled:
                return true
            case let .Fail(e):
                return e.testForCancellation
            default:
                return false
            }
        }
    }
    
    public var isCompleteUsing : Bool {
        get {
            switch self.completion {
            case .CompleteUsing:
                return true
            default:
                return false
            }
        }
    }
    
    internal var completeUsingFuture:Future<T>! {
        get {
            switch self.completion {
            case let .CompleteUsing(f):
                return f
            default:
                return nil
            }
        }
    }


    
    var result : FutureResult<T>!  {
        
        switch self.completion {
            case .CompleteUsing:
                return nil
            case let .Success(value):
                return .Success(value)
            case let .Fail(error):
                return error.toResult() // check for possible cancellation errors
            case .Cancelled:
                return .Cancelled
        }
        
    }
    

    
    /** 
    can be used inside a do/try/catch block to 'try' and get the result of a Future.
    
    Useful if you want to use a swift 2.0 error handling block to resolve errors
    
        let f: Future<Int> = samplefunction()
        f.onComplete { (value) -> Void in
            do {
                let r: Int = try resultValue()
            }
            catch {
                print("error : \(error)")
            }
        }
    
    */
    func tryValue() throws -> T {
        switch self.completion {
        case let .Success(value):
            return value
        case let .Fail(error):
            throw error
        case .Cancelled:
            throw FutureKitError(genericError: "Future was canceled.")
        case let .CompleteUsing(f):
            if let v = f.value {
                return v
            }
            throw FutureKitError(genericError: "Future was not completed.")
        }
    }
    
    /**
    can be used inside a do/try/catch block to 'try' and get the result of a Future.
    
    Useful if you want to use a swift 2.0 error handling block to resolve errors
    
        let f: Future<Int> = samplefunction()
        f.onComplete { (value) -> Void in
            do {
                try throwIfFail()
            }
            catch {
                print("error : \(error)")
            }
        }`
    
    .Cancelled does not throw an error.  If you want to also trap cancellations use 'throwIfFailOrCancel()`
    
    */
    func throwIfFail() throws {
        switch self.completion {
        case let .Fail(error):
            if (!error.testForCancellation) {
                throw error
            }
        default:
            break
        }
    }

    /**
    can be used inside a do/try/catch block to 'try' and get the result of a Future.
    
    Useful if you want to use a swift 2.0 error handling block to resolve errors
    
        let f: Future<Int> = samplefunction()
        f.onComplete { (value) -> Void in
            do {
                try throwIfFailOrCancel()
            }
            catch {
                print("error : \(error)")
            }
        }
    
    */
    func throwIfFailOrCancel() throws {
        switch self.completion {
        case let .Fail(error):
            throw error
        case .Cancelled:
            throw FutureKitError(genericError: "Future was canceled.")
        default:
            break
        }
    }
    
    
    /**
     convert this completion of type Completion<T> into another type Completion<S>.
     
     may fail to compile if T is not convertable into S using "`as!`"
     
     works iff the following code works:
     
     'let t : T`
     
     'let s = t as! S'
     
     
     - example:
     
     `let c : Complete<Int> = .Success(5)`
     
     `let c2 : Complete<Int32> =  c.mapAs()`
     
     `assert(c2.result == Int32(5))`
     
     you will need to formally declare the type of the new variable, in order for Swift to perform the correct conversion.
     */

    public func map<__Type>(block:(T) throws -> __Type) -> Completion<__Type> {
        
        switch self.completion {
        case let .Success(t):
            do {
                return .Success(try block(t))
            }
            catch {
                return .Fail(error)
            }
        case let .Fail(f):
            return .Fail(f)
        case .Cancelled:
            return .Cancelled
        case let .CompleteUsing(f):
            
            let mapf :Future<__Type> = f.map(.Primary,block: block)
            return .CompleteUsing(mapf)
        }
    }
    
    /**
     convert this completion of type `Completion<T>` into another type `Completion<S?>`.
     
     WARNING: if `T as! S` isn't legal, than all Success values may be converted to nil
     - example:
     
     let c : Complete<String> = .Success("5")
     let c2 : Complete<[Int]?> =  c.convertOptional()
     assert(c2.result == nil)
     
     you will need to formally declare the type of the new variable, in order for Swift to perform the correct conversion.
     
     - returns: a new result of type Completion<S?>
     
     */
    public func mapAsOptional<O : OptionalProtocol>() -> Completion<O.Wrapped?> {

        return self.map { v -> O.Wrapped? in
            return v as? O.Wrapped
        }

    }
    
    /**
     convert this completion of type Completion<T> into another type Completion<S>.
     
     may fail to compile if T is not convertable into S using "`as!`"
     
     works iff the following code works:
     
     'let t : T`
     
     'let s = t as! S'
     
     
     - example:
     
     `let c : Complete<Int> = .Success(5)`
     
     `let c2 : Complete<Int32> =  c.mapAs()`
     
     `assert(c2.result == Int32(5))`
     
     you will need to formally declare the type of the new variable, in order for Swift to perform the correct conversion.
     */
    public func mapAs<__Type>() -> Completion<__Type> {
        switch self.completion {
        case let .Success(t):
            let r = t as! __Type
            return .Success(r)
        case let .Fail(f):
            return .Fail(f)
        case .Cancelled:
            return .Cancelled
        case let .CompleteUsing(f):
            return .CompleteUsing(f.mapAs())
        }
    }


    public func As() -> Completion<T> {
        return self.completion
    }
    
    @available(*, deprecated=1.1, message="renamed to mapAs()")
    public func As<__Type>() -> Completion<__Type> {
        return self.mapAs()
    }
    
}


extension FutureResult : CustomStringConvertible, CustomDebugStringConvertible {
    
    public var description: String {
        switch self {
        case let .Success(result):
            return ".Success<\(T.self)>(\(result))"
        case let .Fail(error):
            return ".Fail<\(T.self)>(\(error))"
        case .Cancelled:
            return ".Cancelled<\(T.self)>)"
        }
    }
    public var debugDescription: String {
        return self.description
    }
    
    /**
    This doesn't seem to work yet in the XCode Debugger or Playgrounds.
    it seems that only NSObjectProtocol objects can use this method.
    Since this is a Swift Generic, it seems to be ignored.
    Sigh.
    */
    func debugQuickLookObject() -> AnyObject? {
        return self.debugDescription
    }
}






public extension Completion { // initializers
    
    /**
    returns a .Fail(FutureNSError) with a simple error string message.
    */
    public init(failWithErrorMessage : String) {
        self = .Fail(FutureKitError(genericError: failWithErrorMessage))
    }
    /**
    converts an NSException into an NSError.
    useful for generic Objective-C excecptions into a Future
    */
    public init(exception ex:NSException) {
        self = .Fail(FutureKitError(exception: ex))
    }
    
    public init(success:T) {
        self = .Success(success)
    }

    public init(fail: ErrorType) {
        self = fail.toCompletion() // make sure it's not really a cancellation
    }
    public init(cancelled: ()) {
        self = .Cancelled
    }
    public init(completeUsing:Future<T>){
        self = .CompleteUsing(completeUsing)
    }

}

extension CompletionType {
    
    @available(*, deprecated=1.1, message="depricated use completion",renamed="completion")
    func asCompletion() -> Completion<T> {
        return self.completion
    }
    
    @available(*, deprecated=1.1, message="depricated use result",renamed="result")
    func asResult() -> FutureResult<T> {
        return self.result
    }
    
}




extension CompletionType  {
    
    public var description: String {
        switch self.completion {
        case let .Success(t):
            return "\(Self.self).CompletionType.Success<\(T.self)>(\(t))"
        case let .Fail(f):
            return "\(Self.self).CompletionType.Fail<\(T.self)>(\(f))"
        case let .Cancelled(reason):
            return "\(Self.self).CompletionType.Cancelled<\(T.self)>(\(reason))"
        case let .CompleteUsing(f):
            return "\(Self.self).CompletionType.CompleteUsing<\(T.self)>(\(f.description))"
        }
    }
    public var debugDescription: String {
        return self.description
    }
    
    /**
    This doesn't seem to work yet in the XCode Debugger or Playgrounds.
    it seems that only NSObjectProtocol objects can use this method.
    Since this is a Swift Generic, it seems to be ignored.
    Sigh.
    */
    func debugQuickLookObject() -> AnyObject? {
        return self.debugDescription
    }
}

 